<mujoco model="4_dof_arm_gripper">
    <option timestep="0.002" />
    <worldbody>
        <!-- Base -->
        <body name="base" pos="0 0 0">
            <joint name="joint1" type="hinge" axis="0 0 1" limited="true" range="-180 180"/>
            <geom type="cylinder" size="0.1 0.2" rgba="0.6 0.6 0.6 1"/>

            <!-- First segment -->
            <body name="segment1" pos="0 0.2 0">
                <geom type="capsule" fromto="0 0 0 0 0.4 0" size="0.1" rgba="0.8 0.1 0.1 1"/>
                <joint name="joint2" type="hinge" axis="0 1 0" pos="0 0.4 0" limited="true" range="-90 90"/>

                <!-- Second segment -->
                <body name="segment2" pos="0 0.4 0">
                    <geom type="capsule" fromto="0 0 0 0 0.4 0" size="0.1" rgba="0.1 0.8 0.1 1"/>
                    <joint name="joint3" type="hinge" axis="0 0 1" pos="0 0.4 0" limited="true" range="-180 180"/>

                    <!-- Third segment -->
                    <body name="segment3" pos="0 0.4 0">
                        <geom type="capsule" fromto="0 0 0 0 0.4 0" size="0.1" rgba="0.8 0.8 0.1 1"/>
                        <joint name="joint4" type="hinge" axis="0 1 0" pos="0 0.4 0" limited="true" range="-90 90"/>

                        <!-- End effector -->
                        <body name="end_effector" pos="0 0.4 0">
                            <geom type="sphere" size="0.1" rgba="0.1 0.1 0.8 1"/>

                            <!-- Gripper base -->
                            <body name="gripper_base" pos="0 0.1 0">
                                <!-- Left finger -->
                                <body name="left_finger" pos="-0.15 0.1 0">
                                    <geom type="box" size="0.05 0.1 0.05" rgba="0.3 0.3 0.3 1"/>
                                    <joint name="left_finger_joint" type="slide" axis="1 0 0" limited="true" range="0 0.15"/>
                                </body>
                                <!-- Right finger -->
                                <body name="right_finger" pos="0.15 0.1 0">
                                    <geom type="box" size="0.05 0.1 0.05" rgba="0.3 0.3 0.3 1"/>
                                    <joint name="right_finger_joint" type="slide" axis="-1 0 0" limited="true" range="0 0.15"/>
                                </body>
                            </body>
                        </body>
                    </body>
                </body>
            </body>
        </body>
    </worldbody>
    <actuator>
        <motor name="motor1" joint="joint1" gear="100"/>
        <motor name="motor2" joint="joint2" gear="100"/>
        <motor name="motor3" joint="joint3" gear="100"/>
        <motor name="motor4" joint="joint4" gear="100"/>
        <motor name="motor5" joint="left_finger_joint" gear="100"/>
        <motor name="motor6" joint="right_finger_joint" gear="100"/>
    </actuator>
</mujoco>